Workbook

Sheet README
A1: Macquarie FY24 ESG: data science mini project (pure Excel, no macros or code)
A3: How to run
A4: Open this workbook in desktop Excel (2010+) and click Enable Editing. Nothing else to run or install.
A5: Change the yellow cells on Inputs (starting cluster centres, anomaly threshold); every sheet recalculates. Press F9 if calculation is manual.
A7: Pipeline (each step feeds the next)
A8: 1. Features: feature engineering + z-score standardisation + correlation matrix.
A9: 2. PCA: eigenvectors obtained by power iteration and deflation (PC1, PC2, explained variance, loadings, scores).
A10: 3. KMeans: k = 3 clustering with 8 iterations laid out step by step, convergence check and inertia.
A11: 4. Silhouette: pairwise distance matrix and silhouette score to validate the clusters.
A12: 5. Regression: LINEST multiple regression (t-stats, p-values, F, VIF), train/test split, naive-baseline comparison, residual anomaly flags.
A14: Data from the original locked file
A15: Data sheet = values copied from "1. ESRM" (reviews by sector, FY22 to FY24), source cells listed per row, reconciled to the reported totals.
... A20: Train/test assignment (seed 42) was fixed once and hardcoded in Regression column A.

Sheet Dashboard
A1: Dashboard
A2: Live: change Inputs and everything recalculates.
A3: Metric | B3: Value
A4: PC1 explained variance | B4: =PCA!T5 -> 0.59845603
A5: PC1 + PC2 cumulative | B5: =PCA!U6 -> 0.84933475
A6: K-means converged? | B6: =KMeans!B70 -> Yes
A7: K-means inertia | B7: =KMeans!B71 -> 18.623964
A8: Mean silhouette | B8: =Silhouette!Y23 -> 0.38149515
A9: Cluster 1 / 2 / 3 sizes | B9: =KMeans!B74&" / "&KMeans!B75&" / "&KMeans!B76 -> 3 / 2 / 11
A10: Regression R² (train) | B10: =Regression!K11 -> 0.49133669
A11: Adjusted R² (train) | B11: =Regression!K12 -> 0.3783004
A12: Test RMSE: model | B12: =Regression!B29 -> 19.957442
A13: Test RMSE: naive baseline | B13: =Regression!C29 -> 44.61502
A14: Skill vs naive | B14: =Regression!B32 -> 0.55267436
A15: Anomalous residuals (train + test) | B15: =COUNTIF(Regression!H6:H17,"Anomaly")+COUNTIF(Regression!J22:J25,"Anomaly") -> 3
A17: PCA chart colours assume the default cluster centre inputs (cluster sizes 3 / 2 / 11); other inputs may mis-colour points but not move them.

Sheet Inputs
A1: Inputs (edit yellow cells)
A3: Parameter | B3: Value | C3: Note
A4: K-means initial cluster centre 1 | B4: Mining | C4: Sector used as starting centre of cluster 1
A5: K-means initial cluster centre 2 | B5: Nuclear | C5: Sector used as starting centre of cluster 2
A6: K-means initial cluster centre 3 | B6: Technology | C6: Sector used as starting centre of cluster 3
A7: Residual anomaly threshold |z| | B7: 1.5 | C7: Regression residuals beyond this many std errors are flagged
A9: Fixed design choices (not inputs): k = 3 clusters, 8 k-means iterations, 30 power-iteration steps, 4 PCA features, 12/4 train/test split (seed 42).

Sheet Data
A1: Source data: Macquarie FY24 ESG Dataset, sheet "1. ESRM"
A2: Blue = values copied from the (protected) source file; source cells listed per row. Columns reordered oldest to newest.
A3: Reviews completed under the ESR Policy, by sector (#)
A4: Sector | B4: FY22 | C4: FY23 | D4: FY24 | E4: Source cells
A5: Mining | B5: 215 | C5: 249 | D5: 167 | E5: '1. ESRM'!B5:E5
A6: Energy | B6: 192 | C6: 195 | D6: 165 | E6: '1. ESRM'!B6:E6
A7: Social infrastructure | B7: 83 | C7: 87 | D7: 107 | E7: '1. ESRM'!B7:E7
A8: Nuclear | B8: 33 | C8: 27 | D8: 66 | E8: '1. ESRM'!B8:E8
A9: Defence | B9: 43 | C9: 45 | D9: 54 | E9: '1. ESRM'!B9:E9
A10: Agriculture | B10: 39 | C10: 60 | D10: 47 | E10: '1. ESRM'!B10:E10
A11: Manufacturing | B11: 44 | C11: 48 | D11: 46 | E11: '1. ESRM'!B11:E11
A12: Financial services | B12: 54 | C12: 60 | D12: 44 | E12: '1. ESRM'!B12:E12
A13: Gaming & entertainment | B13: 42 | C13: 53 | D13: 40 | E13: '1. ESRM'!B13:E13
A14: Chemicals & pharmaceuticals | B14: 52 | C14: 54 | D14: 33 | E14: '1. ESRM'!B14:E14
A15: Renewables | B15: 46 | C15: 23 | D15: 30 | E15: '1. ESRM'!B15:E15
A16: Forestry | B16: 11 | C16: 20 | D16: 29 | E16: '1. ESRM'!B16:E16
... A20: Other | B20: 72 | C20: 78 | D20: 60 | E20: '1. ESRM'!B20:E20
A21: Total (calculated) | B21: =SUM(B5:B20) -> 1041 | C21: =SUM(C5:C20) -> 1094 | D21: =SUM(D5:D20) -> 961
A22: Total (reported) | B22: 1041 | C22: 1094 | D22: 961 | E22: '1. ESRM'!C21:E21
A23: Check (should be 0) | B23: =B21-B22 -> 0 | C23: =C21-C22 -> 0 | D23: =D21-D22 -> 0

Sheet Features
A1: Step 1: Feature engineering and standardisation
A2: Each sector becomes a 4-feature profile, then z-scored (mean 0, std 1) so features are comparable.
A4: Period index t | B4: 1 | C4: 2 | D4: 3
A5: Sector | B5: FY22 | C5: FY23 | D5: FY24 | E5: ln(avg volume) | F5: YoY growth FY24 | G5: Volatility (CV) | H5: Relative trend | I5: z: ln(avg volume) | J5: z: YoY growth FY24 | K5: z: Volatility (CV) | L5: z: Relative trend
A6: =Data!A5 -> Mining | B6: =Data!B5 -> 215 | C6: =Data!C5 -> 249 | D6: =Data!D5 -> 167 | E6: =LN(AVERAGE(B6:D6)) -> 5.3486936 | F6: =IF(C6=0,0,D6/C6-1) -> -0.32931727 | G6: =STDEV(B6:D6)/AVERAGE(B6:D6) -> 0.1958734 | H6: =SLOPE(B6:D6,$B$4:$D$4)/AVERAGE(B6:D6) -> -0.1141046 | I6: =(E6-E$22)/E$23 -> 2.2282166 | J6: =(F6-F$22)/F$23 -> -0.72394527 | K6: =(G6-G$22)/G$23 -> -0.19392696 | L6: =(H6-H$22)/H$23 -> -0.44607581
A7: =Data!A6 -> Energy | B7: =Data!B6 -> 192 | C7: =Data!C6 -> 195 | D7: =Data!D6 -> 165 | E7: =LN(AVERAGE(B7:D7)) -> 5.2149358 | F7: =IF(C7=0,0,D7/C7-1) -> -0.15384615 | G7: =STDEV(B7:D7)/AVERAGE(B7:D7) -> 0.089797346 | H7: =SLOPE(B7:D7,$B$4:$D$4)/AVERAGE(B7:D7) -> -0.073369565 | I7: =(E7-E$22)/E$23 -> 2.0162355 | J7: =(F7-F$22)/F$23 -> -0.34335418 | K7: =(G7-G$22)/G$23 -> -1.0432511 | L7: =(H7-H$22)/H$23 -> -0.25383652
A8: =Data!A7 -> Social infrastructure | B8: =Data!B7 -> 83 | C8: =Data!C7 -> 87 | D8: =Data!D7 -> 107 | E8: =LN(AVERAGE(B8:D8)) -> 4.5254052 | F8: =IF(C8=0,0,D8/C8-1) -> 0.22988506 | G8: =STDEV(B8:D8)/AVERAGE(B8:D8) -> 0.13925849 | H8: =SLOPE(B8:D8,$B$4:$D$4)/AVERAGE(B8:D8) -> 0.1299639 | I8: =(E8-E$22)/E$23 -> 0.9234591 | J8: =(F8-F$22)/F$23 -> 0.48894622 | K8: =(G8-G$22)/G$23 -> -0.64722817 | L8: =(H8-H$22)/H$23 -> 0.70574737
A9: =Data!A8 -> Nuclear | B9: =Data!B8 -> 33 | C9: =Data!C8 -> 27 | D9: =Data!D8 -> 66 | E9: =LN(AVERAGE(B9:D9)) -> 3.7376696 | F9: =IF(C9=0,0,D9/C9-1) -> 1.4444444 | G9: =STDEV(B9:D9)/AVERAGE(B9:D9) -> 0.5 | H9: =SLOPE(B9:D9,$B$4:$D$4)/AVERAGE(B9:D9) -> 0.39285714 | I9: =(E9-E$22)/E$23 -> -0.32495391 | J9: =(F9-F$22)/F$23 -> 3.1232857 | K9: =(G9-G$22)/G$23 -> 2.2411376 | L9: =(H9-H$22)/H$23 -> 1.9464095
A10: =Data!A9 -> Defence | B10: =Data!B9 -> 43 | C10: =Data!C9 -> 45 | D10: =Data!D9 -> 54 | E10: =LN(AVERAGE(B10:D10)) -> 3.8572148 | F10: =IF(C10=0,0,D10/C10-1) -> 0.2 | G10: =STDEV(B10:D10)/AVERAGE(B10:D10) -> 0.12379152 | H10: =SLOPE(B10:D10,$B$4:$D$4)/AVERAGE(B10:D10) -> 0.11619718 | I10: =(E10-E$22)/E$23 -> -0.13549729 | J10: =(F10-F$22)/F$23 -> 0.42412651 | K10: =(G10-G$22)/G$23 -> -0.77106832 | L10: =(H10-H$22)/H$23 -> 0.64077863
A11: =Data!A10 -> Agriculture | B11: =Data!B10 -> 39 | C11: =Data!C10 -> 60 | D11: =Data!D10 -> 47 | E11: =LN(AVERAGE(B11:D11)) -> 3.8849943 | F11: =IF(C11=0,0,D11/C11-1) -> -0.21666667 | G11: =STDEV(B11:D11)/AVERAGE(B11:D11) -> 0.21778237 | H11: =SLOPE(B11:D11,$B$4:$D$4)/AVERAGE(B11:D11) -> 0.082191781 | I11: =(E11-E$22)/E$23 -> -0.0914719 | J11: =(F11-F$22)/F$23 -> -0.47960981 | K11: =(G11-G$22)/G$23 -> -0.018507391 | L11: =(H11-H$22)/H$23 -> 0.48029823
A12: =Data!A11 -> Manufacturing | B12: =Data!B11 -> 44 | C12: =Data!C11 -> 48 | D12: =Data!D11 -> 46 | E12: =LN(AVERAGE(B12:D12)) -> 3.8286414 | F12: =IF(C12=0,0,D12/C12-1) -> -0.041666667 | G12: =STDEV(B12:D12)/AVERAGE(B12:D12) -> 0.043478261 | H12: =SLOPE(B12:D12,$B$4:$D$4)/AVERAGE(B12:D12) -> 0.02173913 | I12: =(E12-E$22)/E$23 -> -0.18078072 | J12: =(F12-F$22)/F$23 -> -0.10004056 | K12: =(G12-G$22)/G$23 -> -1.4141162 | L12: =(H12-H$22)/H$23 -> 0.19500633
A13: =Data!A12 -> Financial services | B13: =Data!B12 -> 54 | C13: =Data!C12 -> 60 | D13: =Data!D12 -> 44 | E13: =LN(AVERAGE(B13:D13)) -> 3.9639827 | F13: =IF(C13=0,0,D13/C13-1) -> -0.26666667 | G13: =STDEV(B13:D13)/AVERAGE(B13:D13) -> 0.15347286 | H13: =SLOPE(B13:D13,$B$4:$D$4)/AVERAGE(B13:D13) -> -0.094936709 | I13: =(E13-E$22)/E$23 -> 0.0337099 | J13: =(F13-F$22)/F$23 -> -0.58805817 | K13: =(G13-G$22)/G$23 -> -0.53341738 | L13: =(H13-H$22)/H$23 -> -0.35561753
A14: =Data!A13 -> Gaming & entertainment | B14: =Data!B13 -> 42 | C14: =Data!C13 -> 53 | D14: =Data!D13 -> 40 | E14: =LN(AVERAGE(B14:D14)) -> 3.8066625 | F14: =IF(C14=0,0,D14/C14-1) -> -0.24528302 | G14: =STDEV(B14:D14)/AVERAGE(B14:D14) -> 0.15555556 | H14: =SLOPE(B14:D14,$B$4:$D$4)/AVERAGE(B14:D14) -> -0.022222222 | I14: =(E14-E$22)/E$23 -> -0.21561316 | J14: =(F14-F$22)/F$23 -> -0.54167774 | K14: =(G14-G$22)/G$23 -> -0.51674174 | L14: =(H14-H$22)/H$23 -> -0.012458812
A15: =Data!A14 -> Chemicals & pharmaceuticals | B15: =Data!B14 -> 52 | C15: =Data!C14 -> 54 | D15: =Data!D14 -> 33 | E15: =LN(AVERAGE(B15:D15)) -> 3.8358616 | F15: =IF(C15=0,0,D15/C15-1) -> -0.38888889 | G15: =STDEV(B15:D15)/AVERAGE(B15:D15) -> 0.25014876 | H15: =SLOPE(B15:D15,$B$4:$D$4)/AVERAGE(B15:D15) -> -0.20503597 | I15: =(E15-E$22)/E$23 -> -0.16933799 | J15: =(F15-F$22)/F$23 -> -0.85315416 | K15: =(G15-G$22)/G$23 -> 0.24064206 | L15: =(H15-H$22)/H$23 -> -0.87520479
A16: =Data!A15 -> Renewables | B16: =Data!B15 -> 46 | C16: =Data!C15 -> 23 | D16: =Data!D15 -> 30 | E16: =LN(AVERAGE(B16:D16)) -> 3.4965076 | F16: =IF(C16=0,0,D16/C16-1) -> 0.30434783 | G16: =STDEV(B16:D16)/AVERAGE(B16:D16) -> 0.35726746 | H16: =SLOPE(B16:D16,$B$4:$D$4)/AVERAGE(B16:D16) -> -0.24242424 | I16: =(E16-E$22)/E$23 -> -0.70715049 | J16: =(F16-F$22)/F$23 -> 0.65045352 | K16: =(G16-G$22)/G$23 -> 1.0983144 | L16: =(H16-H$22)/H$23 -> -1.0516498
A17: =Data!A16 -> Forestry | B17: =Data!B16 -> 11 | C17: =Data!C16 -> 20 | D17: =Data!D16 -> 29 | E17: =LN(AVERAGE(B17:D17)) -> 2.9957323 | F17: =IF(C17=0,0,D17/C17-1) -> 0.45 | G17: =STDEV(B17:D17)/AVERAGE(B17:D17) -> 0.45 | H17: =SLOPE(B17:D17,$B$4:$D$4)/AVERAGE(B17:D17) -> 0.45 | I17: =(E17-E$22)/E$23 -> -1.5007853 | J17: =(F17-F$22)/F$23 -> 0.96636831 | K17: =(G17-G$22)/G$23 -> 1.8408003 | L17: =(H17-H$22)/H$23 -> 2.2160816
... A21: =Data!A20 -> Other | B21: =Data!B20 -> 72 | C21: =Data!C20 -> 78 | D21: =Data!D20 -> 60 | E21: =LN(AVERAGE(B21:D21)) -> 4.2484952 | F21: =IF(C21=0,0,D21/C21-1) -> -0.23076923 | G21: =STDEV(B21:D21)/AVERAGE(B21:D21) -> 0.13093073 | H21: =SLOPE(B21:D21,$B$4:$D$4)/AVERAGE(B21:D21) -> -0.085714286 | I21: =(E21-E$22)/E$23 -> 0.48460879 | J21: =(F21-F$22)/F$23 -> -0.51019781 | K21: =(G21-G$22)/G$23 -> -0.71390644 | L21: =(H21-H$22)/H$23 -> -0.31209449
A22: Mean | E22: =AVERAGE(E6:E21) -> 3.9427121 | F22: =AVERAGE(F6:F21) -> 0.0044569245 | G22: =AVERAGE(G6:G21) -> 0.22009385 | H22: =AVERAGE(H6:H21) -> -0.019582231
A23: Std dev (sample) | E23: =STDEV(E6:E21) -> 0.63098958 | F23: =STDEV(F6:F21) -> 0.46104893 | G23: =STDEV(G6:G21) -> 0.12489467 | H23: =STDEV(H6:H21) -> 0.21189754
A25: Correlation matrix of the 4 features (input to PCA)
B26: ln(avg volume) | C26: YoY growth FY24 | D26: Volatility (CV) | E26: Relative trend
A27: ln(avg volume) | B27: =CORREL(E$6:E$21,E$6:E$21) -> 1 | C27: =CORREL(E$6:E$21,F$6:F$21) -> -0.23412028 | D27: =CORREL(E$6:E$21,G$6:G$21) -> -0.51423781 | E27: =CORREL(E$6:E$21,H$6:H$21) -> -0.13188328
A28: YoY growth FY24 | B28: =CORREL(F$6:F$21,E$6:E$21) -> -0.23412028 | C28: =CORREL(F$6:F$21,F$6:F$21) -> 1 | D28: =CORREL(F$6:F$21,G$6:G$21) -> 0.66176399 | E28: =CORREL(F$6:F$21,H$6:H$21) -> 0.72664853
A29: Volatility (CV) | B29: =CORREL(G$6:G$21,E$6:E$21) -> -0.51423781 | C29: =CORREL(G$6:G$21,F$6:F$21) -> 0.66176399 | D29: =CORREL(G$6:G$21,G$6:G$21) -> 1 | E29: =CORREL(G$6:G$21,H$6:H$21) -> 0.41244325
A30: Relative trend | B30: =CORREL(H$6:H$21,E$6:E$21) -> -0.13188328 | C30: =CORREL(H$6:H$21,F$6:F$21) -> 0.72664853 | D30: =CORREL(H$6:H$21,G$6:G$21) -> 0.41244325 | E30: =CORREL(H$6:H$21,H$6:H$21) -> 1

Sheet PCA
A1: Step 2: PCA via eigenvectors (power iteration with deflation)
A2: Excel has no eigen function, so PC1 and PC2 are obtained by repeated matrix-vector multiplication until the vector stops changing (column J shows convergence).
A3: Correlation matrix C | R3: Results
B4: ln(avg volume) | C4: YoY growth FY24 | D4: Volatility (CV) | E4: Relative trend | L4: Sector | M4: PC1 score | N4: PC2 score | O4: Cluster | P4: Sort key | R4: Component | S4: Eigenvalue | T4: Explained variance | U4: Cumulative
A5: ln(avg volume) | B5: =Features!B27 -> 1 | C5: =Features!C27 -> -0.23412028 | D5: =Features!D27 -> -0.51423781 | E5: =Features!E27 -> -0.13188328 | L5: =Features!A6 -> Mining | M5: =SUMPRODUCT(Features!I6:L6,$B$42:$E$42) -> -1.5170605 | N5: =SUMPRODUCT(Features!I6:L6,$B$85:$E$85) -> -1.3457853 | O5: =KMeans!F6 -> 1 | P5: =O5*100+1 -> 101 | R5: PC1 | S5: =SUMPRODUCT(F42:I42,B42:E42) -> 2.3938241 | T5: =S5/4 -> 0.59845603 | U5: =T5 -> 0.59845603
A6: YoY growth FY24 | B6: =Features!B28 -> -0.23412028 | C6: =Features!C28 -> 1 | D6: =Features!D28 -> 0.66176399 | E6: =Features!E28 -> 0.72664853 | L6: =Features!A7 -> Energy | M6: =SUMPRODUCT(Features!I7:L7,$B$42:$E$42) -> -1.5945419 | N6: =SUMPRODUCT(Features!I7:L7,$B$85:$E$85) -> -1.613388 | O6: =KMeans!F7 -> 1 | P6: =O6*100+2 -> 102 | R6: PC2 | S6: =SUMPRODUCT(F85:I85,B85:E85) -> 1.0035149 | T6: =S6/4 -> 0.25087872 | U6: =U5+T6 -> 0.84933475
A7: Volatility (CV) | B7: =Features!B29 -> -0.51423781 | C7: =Features!C29 -> 0.66176399 | D7: =Features!D29 -> 1 | E7: =Features!E29 -> 0.41244325 | L7: =Features!A8 -> Social infrastructure | M7: =SUMPRODUCT(Features!I8:L8,$B$42:$E$42) -> -0.0425459 | N7: =SUMPRODUCT(Features!I8:L8,$B$85:$E$85) -> -1.3787266 | O7: =KMeans!F8 -> 1 | P7: =O7*100+3 -> 103
A8: Relative trend | B8: =Features!B30 -> -0.13188328 | C8: =Features!C30 -> 0.72664853 | D8: =Features!D30 -> 0.41244325 | E8: =Features!E30 -> 1 | L8: =Features!A9 -> Nuclear | M8: =SUMPRODUCT(Features!I9:L9,$B$42:$E$42) -> 4.1101016 | N8: =SUMPRODUCT(Features!I9:L9,$B$85:$E$85) -> -1.0297504 | O8: =KMeans!F9 -> 2 | P8: =O8*100+4 -> 204 | R8: Loading | S8: PC1 | T8: PC2
L9: =Features!A10 -> Defence | M9: =SUMPRODUCT(Features!I10:L10,$B$42:$E$42) -> 0.1865673 | N9: =SUMPRODUCT(Features!I10:L10,$B$85:$E$85) -> -0.53991745 | O9: =KMeans!F10 -> 3 | P9: =O9*100+5 -> 305 | R9: ln(avg volume) | S9: =B42 -> -0.34627103 | T9: =B85 -> -0.77493578
A10: PC1: power iteration on C | L10: =Features!A11 -> Agriculture | M10: =SUMPRODUCT(Features!I11:L11,$B$42:$E$42) -> -0.017078677 | N10: =SUMPRODUCT(Features!I11:L11,$B$85:$E$85) -> -0.029864626 | O10: =KMeans!F11 -> 3 | P10: =O10*100+6 -> 306 | R10: YoY growth FY24 | S10: =C42 -> 0.57719536 | T10: =C85 -> -0.29365249
A11: Iter | B11: v1 | C11: v2 | D11: v3 | E11: v4 | F11: C·v 1 | G11: C·v 2 | H11: C·v 3 | I11: C·v 4 | J11: Change | L11: =Features!A12 -> Manufacturing | M11: =SUMPRODUCT(Features!I12:L12,$B$42:$E$42) -> -0.67415705 | N11: =SUMPRODUCT(Features!I12:L12,$B$85:$E$85) -> -0.3018833 | O11: =KMeans!F12 -> 3 | P11: =O11*100+7 -> 307 | R11: Volatility (CV) | S11: =D42 -> 0.54856632 | T11: =D85 -> 0.26536753
A12: 0 | B12: 0.5 | C12: 0.5 | D12: 0.5 | E12: 0.5 | F12: =SUMPRODUCT($B$5:$E$5,$B12:$E12) -> 0.05987931 | G12: =SUMPRODUCT($B$6:$E$6,$B12:$E12) -> 1.0771461 | H12: =SUMPRODUCT($B$7:$E$7,$B12:$E12) -> 0.77998471 | I12: =SUMPRODUCT($B$8:$E$8,$B12:$E12) -> 1.0036043 | L12: =Features!A13 -> Financial services | M12: =SUMPRODUCT(Features!I13:L13,$B$42:$E$42) -> -0.82009863 | N12: =SUMPRODUCT(Features!I13:L13,$B$85:$E$85) -> 0.18024794 | O12: =KMeans!F13 -> 3 | P12: =O12*100+8 -> 308 | R12: Relative trend | S12: =E42 -> 0.49600088 | T12: =E85 -> -0.49277057
A13: 1 | B13: =F12/SQRT(SUMSQ($F12:$I12)) -> 0.035916926 | C13: =G12/SQRT(SUMSQ($F12:$I12)) -> 0.64609591 | D13: =H12/SQRT(SUMSQ($F12:$I12)) -> 0.46785197 | E13: =I12/SQRT(SUMSQ($F12:$I12)) -> 0.60198388 | F13: =SUMPRODUCT($B$5:$E$5,$B13:$E13) -> -0.43532601 | G13: =SUMPRODUCT($B$6:$E$6,$B13:$E13) -> 1.3847253 | H13: =SUMPRODUCT($B$7:$E$7,$B13:$E13) -> 1.1252293 | I13: =SUMPRODUCT($B$8:$E$8,$B13:$E13) -> 1.2596941 | J13: =SQRT(SUMXMY2(B13:E13,B12:E12)) -> 0.49814789 | L13: =Features!A14 -> Gaming & entertainment | M13: =SUMPRODUCT(Features!I14:L14,$B$42:$E$42) -> -0.52763998 | N13: =SUMPRODUCT(Features!I14:L14,$B$85:$E$85) -> 0.19516423 | O13: =KMeans!F14 -> 3 | P13: =O13*100+9 -> 309
A14: 2 | B14: =F13/SQRT(SUMSQ($F13:$I13)) -> -0.19546827 | C14: =G13/SQRT(SUMSQ($F13:$I13)) -> 0.62176359 | D14: =H13/SQRT(SUMSQ($F13:$I13)) -> 0.50524578 | E14: =I13/SQRT(SUMSQ($F13:$I13)) -> 0.56562258 | F14: =SUMPRODUCT($B$5:$E$5,$B14:$E14) -> -0.67544839 | G14: =SUMPRODUCT($B$6:$E$6,$B14:$E14) -> 1.412889 | H14: =SUMPRODUCT($B$7:$E$7,$B14:$E14) -> 1.2505109 | I14: =SUMPRODUCT($B$8:$E$8,$B14:$E14) -> 1.2515904 | J14: =SQRT(SUMXMY2(B14:E14,B13:E13)) -> 0.23843576 | L14: =Features!A15 -> Chemicals & pharmaceuticals | M14: =SUMPRODUCT(Features!I15:L15,$B$42:$E$42) -> -0.73589401 | N14: =SUMPRODUCT(Features!I15:L15,$B$85:$E$85) -> 0.87689066 | O14: =KMeans!F15 -> 3 | P14: =O14*100+10 -> 310 | R14: Orthogonality v1·v2 (≈0) | U14: =SUMPRODUCT(B42:E42,B85:E85) -> 6.6290862e-12
A15: 3 | B15: =F14/SQRT(SUMSQ($F14:$I14)) -> -0.28586988 | C15: =G14/SQRT(SUMSQ($F14:$I14)) -> 0.5979767 | D15: =H14/SQRT(SUMSQ($F14:$I14)) -> 0.52925348 | E15: =I14/SQRT(SUMSQ($F14:$I14)) -> 0.52971034 | F15: =SUMPRODUCT($B$5:$E$5,$B15:$E15) -> -0.76789044 | G15: =SUMPRODUCT($B$6:$E$6,$B15:$E15) -> 1.4000588 | H15: =SUMPRODUCT($B$7:$E$7,$B15:$E15) -> 1.2904535 | I15: =SUMPRODUCT($B$8:$E$8,$B15:$E15) -> 1.2202177 | J15: =SQRT(SUMXMY2(B15:E15,B14:E14)) -> 0.10297731 | L15: =Features!A16 -> Renewables | M15: =SUMPRODUCT(Features!I16:L16,$B$42:$E$42) -> 0.7011835 | N15: =SUMPRODUCT(Features!I16:L16,$B$85:$E$85) -> 1.166668 | O15: =KMeans!F16 -> 3 | P15: =O15*100+11 -> 311 | R15: PC1 converged? | U15: =IF(J42<0.000001,"Yes","No") -> Yes
A16: 4 | B16: =F15/SQRT(SUMSQ($F15:$I15)) -> -0.32152051 | C16: =G15/SQRT(SUMSQ($F15:$I15)) -> 0.58621332 | D16: =H15/SQRT(SUMSQ($F15:$I15)) -> 0.5403209 | E16: =I15/SQRT(SUMSQ($F15:$I15)) -> 0.51091275 | F16: =SUMPRODUCT($B$5:$E$5,$B16:$E16) -> -0.80399922 | G16: =SUMPRODUCT($B$6:$E$6,$B16:$E16) -> 1.3903067 | H16: =SUMPRODUCT($B$7:$E$7,$B16:$E16) -> 1.3043163 | I16: =SUMPRODUCT($B$8:$E$8,$B16:$E16) -> 1.2021387 | J16: =SQRT(SUMXMY2(B16:E16,B15:E15)) -> 0.043418677 | L16: =Features!A17 -> Forestry | M16: =SUMPRODUCT(Features!I17:L17,$B$42:$E$42) -> 3.1864413 | N16: =SUMPRODUCT(Features!I17:L17,$B$85:$E$85) -> 0.27570459 | O16: =KMeans!F17 -> 2 | P16: =O16*100+12 -> 212 | R16: PC2 converged? | U16: =IF(J85<0.000001,"Yes","No") -> Yes
A17: 5 | B17: =F16/SQRT(SUMSQ($F16:$I16)) -> -0.33600025 | C17: =G16/SQRT(SUMSQ($F16:$I16)) -> 0.58102468 | D17: =H16/SQRT(SUMSQ($F16:$I16)) -> 0.54508833 | E17: =I16/SQRT(SUMSQ($F16:$I16)) -> 0.50238717 | F17: =SUMPRODUCT($B$5:$E$5,$B17:$E17) -> -0.81859141 | G17: =SUMPRODUCT($B$6:$E$6,$B17:$E17) -> 1.3854679 | H17: =SUMPRODUCT($B$7:$E$7,$B17:$E17) -> 1.3095798 | I17: =SUMPRODUCT($B$8:$E$8,$B17:$E17) -> 1.1937187 | J17: =SQRT(SUMXMY2(B17:E17,B16:E16)) -> 0.01822083 | L17: =Features!A18 -> Transport | M17: =SUMPRODUCT(Features!I18:L18,$B$42:$E$42) -> -0.37985929 | N17: =SUMPRODUCT(Features!I18:L18,$B$85:$E$85) -> 1.0774228 | O17: =KMeans!F18 -> 3 | P17: =O17*100+13 -> 313 | R17: Total variance = 4 (trace of a 4x4 correlation matrix). Loading signs are arbitrary.
A18: 6 | B18: =F17/SQRT(SUMSQ($F17:$I17)) -> -0.3419841 | C18: =G17/SQRT(SUMSQ($F17:$I17)) -> 0.57880889 | D18: =H17/SQRT(SUMSQ($F17:$I17)) -> 0.54710501 | E18: =I17/SQRT(SUMSQ($F17:$I17)) -> 0.49870157 | F18: =SUMPRODUCT($B$5:$E$5,$B18:$E18) -> -0.82460748 | G18: =SUMPRODUCT($B$6:$E$6,$B18:$E18) -> 1.3833095 | H18: =SUMPRODUCT($B$7:$E$7,$B18:$E18) -> 1.3116871 | I18: =SUMPRODUCT($B$8:$E$8,$B18:$E18) -> 1.190044 | J18: =SQRT(SUMXMY2(B18:E18,B17:E17)) -> 0.0076398208 | L18: =Features!A19 -> Technology | M18: =SUMPRODUCT(Features!I19:L19,$B$42:$E$42) -> -0.38842448 | N18: =SUMPRODUCT(Features!I19:L19,$B$85:$E$85) -> 1.1835452 | O18: =KMeans!F19 -> 3 | P18: =O18*100+14 -> 314
A19: 7 | B19: =F18/SQRT(SUMSQ($F18:$I18)) -> -0.34447719 | C19: =G18/SQRT(SUMSQ($F18:$I18)) -> 0.57787319 | D19: =H18/SQRT(SUMSQ($F18:$I18)) -> 0.54795319 | E19: =I18/SQRT(SUMSQ($F18:$I18)) -> 0.49713714 | F19: =SUMPRODUCT($B$5:$E$5,$B19:$E19) -> -0.82711136 | G19: =SUMPRODUCT($B$6:$E$6,$B19:$E19) -> 1.382382 | H19: =SUMPRODUCT($B$7:$E$7,$B19:$E19) -> 1.3125529 | I19: =SUMPRODUCT($B$8:$E$8,$B19:$E19) -> 1.1884782 | J19: =SQRT(SUMXMY2(B19:E19,B18:E18)) -> 0.0032028001 | L19: =Features!A20 -> Infrastructure | M19: =SUMPRODUCT(Features!I20:L20,$B$42:$E$42) -> -0.47827924 | N19: =SUMPRODUCT(Features!I20:L20,$B$85:$E$85) -> 1.5450487 | O19: =KMeans!F20 -> 3 | P19: =O19*100+15 -> 315
A20: 8 | B20: =F19/SQRT(SUMSQ($F19:$I19)) -> -0.34551961 | C20: =G19/SQRT(SUMSQ($F19:$I19)) -> 0.57747977 | D20: =H19/SQRT(SUMSQ($F19:$I19)) -> 0.54830921 | E20: =I19/SQRT(SUMSQ($F19:$I19)) -> 0.49647793 | F20: =SUMPRODUCT($B$5:$E$5,$B20:$E20) -> -0.8281578 | G20: =SUMPRODUCT($B$6:$E$6,$B20:$E20) -> 1.3819892 | H20: =SUMPRODUCT($B$7:$E$7,$B20:$E20) -> 1.3129127 | I20: =SUMPRODUCT($B$8:$E$8,$B20:$E20) -> 1.1878174 | J20: =SQRT(SUMXMY2(B20:E20,B19:E19)) -> 0.0013426541 | L20: =Features!A21 -> Other | M20: =SUMPRODUCT(Features!I21:L21,$B$42:$E$42) -> -1.008714 | N20: =SUMPRODUCT(Features!I21:L21,$B$85:$E$85) -> -0.26137643 | O20: =KMeans!F21 -> 3 | P20: =O20*100+16 -> 316
A21: 9 | B21: =F20/SQRT(SUMSQ($F20:$I20)) -> -0.34595613 | C21: =G20/SQRT(SUMSQ($F20:$I20)) -> 0.57731463 | D21: =H20/SQRT(SUMSQ($F20:$I20)) -> 0.54845852 | E21: =I20/SQRT(SUMSQ($F20:$I20)) -> 0.49620099 | F21: =SUMPRODUCT($B$5:$E$5,$B21:$E21) -> -0.82859592 | G21: =SUMPRODUCT($B$6:$E$6,$B21:$E21) -> 1.3818238 | H21: =SUMPRODUCT($B$7:$E$7,$B21:$E21) -> 1.313063 | I21: =SUMPRODUCT($B$8:$E$8,$B21:$E21) -> 1.1875397 | J21: =SQRT(SUMXMY2(B21:E21,B20:E20)) -> 0.00056285457
A22: 10 | B22: =F21/SQRT(SUMSQ($F21:$I21)) -> -0.34613904 | C22: =G21/SQRT(SUMSQ($F21:$I21)) -> 0.57724537 | D22: =H21/SQRT(SUMSQ($F21:$I21)) -> 0.54852113 | E22: =I21/SQRT(SUMSQ($F21:$I21)) -> 0.49608479 | F22: =SUMPRODUCT($B$5:$E$5,$B22:$E22) -> -0.82877948 | G22: =SUMPRODUCT($B$6:$E$6,$B22:$E22) -> 1.3817544 | H22: =SUMPRODUCT($B$7:$E$7,$B22:$E22) -> 1.3131259 | I22: =SUMPRODUCT($B$8:$E$8,$B22:$E22) -> 1.1874231 | J22: =SQRT(SUMXMY2(B22:E22,B21:E21)) -> 0.00023595428
A23: 11 | B23: =F22/SQRT(SUMSQ($F22:$I22)) -> -0.3462157 | C23: =G22/SQRT(SUMSQ($F22:$I22)) -> 0.57721633 | D23: =H22/SQRT(SUMSQ($F22:$I22)) -> 0.54854738 | E23: =I22/SQRT(SUMSQ($F22:$I22)) -> 0.49603606 | F23: =SUMPRODUCT($B$5:$E$5,$B23:$E23) -> -0.82885642 | G23: =SUMPRODUCT($B$6:$E$6,$B23:$E23) -> 1.3817252 | H23: =SUMPRODUCT($B$7:$E$7,$B23:$E23) -> 1.3131523 | I23: =SUMPRODUCT($B$8:$E$8,$B23:$E23) -> 1.1873742 | J23: =SQRT(SUMXMY2(B23:E23,B22:E22)) -> 9.8914386e-05 | L23: Scores sorted by cluster (feeds the Dashboard chart)
A24: 12 | B24: =F23/SQRT(SUMSQ($F23:$I23)) -> -0.34624783 | C24: =G23/SQRT(SUMSQ($F23:$I23)) -> 0.57720415 | D24: =H23/SQRT(SUMSQ($F23:$I23)) -> 0.54855838 | E24: =I23/SQRT(SUMSQ($F23:$I23)) -> 0.49601563 | F24: =SUMPRODUCT($B$5:$E$5,$B24:$E24) -> -0.82888867 | G24: =SUMPRODUCT($B$6:$E$6,$B24:$E24) -> 1.381713 | H24: =SUMPRODUCT($B$7:$E$7,$B24:$E24) -> 1.3131633 | I24: =SUMPRODUCT($B$8:$E$8,$B24:$E24) -> 1.1873537 | J24: =SQRT(SUMXMY2(B24:E24,B23:E23)) -> 4.1465895e-05 | L24: Sector | M24: PC1 score | N24: PC2 score | O24: Cluster | P24: Row idx
A25: 13 | B25: =F24/SQRT(SUMSQ($F24:$I24)) -> -0.3462613 | C25: =G24/SQRT(SUMSQ($F24:$I24)) -> 0.57719905 | D25: =H24/SQRT(SUMSQ($F24:$I24)) -> 0.54856299 | E25: =I24/SQRT(SUMSQ($F24:$I24)) -> 0.49600707 | F25: =SUMPRODUCT($B$5:$E$5,$B25:$E25) -> -0.82890218 | G25: =SUMPRODUCT($B$6:$E$6,$B25:$E25) -> 1.3817079 | H25: =SUMPRODUCT($B$7:$E$7,$B25:$E25) -> 1.313168 | I25: =SUMPRODUCT($B$8:$E$8,$B25:$E25) -> 1.1873451 | J25: =SQRT(SUMXMY2(B25:E25,B24:E24)) -> 1.7382915e-05 | L25: =INDEX(L$5:L$20,$P25) -> Mining | M25: =INDEX(M$5:M$20,$P25) -> -1.5170605 | N25: =INDEX(N$5:N$20,$P25) -> -1.3457853 | O25: =INDEX(O$5:O$20,$P25) -> 1 | P25: =MOD(SMALL($P$5:$P$20,1),100) -> 1
A26: 14 | B26: =F25/SQRT(SUMSQ($F25:$I25)) -> -0.34626695 | C26: =G25/SQRT(SUMSQ($F25:$I25)) -> 0.57719691 | D26: =H25/SQRT(SUMSQ($F25:$I25)) -> 0.54856493 | E26: =I25/SQRT(SUMSQ($F25:$I25)) -> 0.49600348 | F26: =SUMPRODUCT($B$5:$E$5,$B26:$E26) -> -0.82890785 | G26: =SUMPRODUCT($B$6:$E$6,$B26:$E26) -> 1.3817057 | H26: =SUMPRODUCT($B$7:$E$7,$B26:$E26) -> 1.3131699 | I26: =SUMPRODUCT($B$8:$E$8,$B26:$E26) -> 1.1873415 | J26: =SQRT(SUMXMY2(B26:E26,B25:E25)) -> 7.2870911e-06 | L26: =INDEX(L$5:L$20,$P26) -> Energy | M26: =INDEX(M$5:M$20,$P26) -> -1.5945419 | N26: =INDEX(N$5:N$20,$P26) -> -1.613388 | O26: =INDEX(O$5:O$20,$P26) -> 1 | P26: =MOD(SMALL($P$5:$P$20,2),100) -> 2
A27: 15 | B27: =F26/SQRT(SUMSQ($F26:$I26)) -> -0.34626932 | C27: =G26/SQRT(SUMSQ($F26:$I26)) -> 0.57719601 | D27: =H26/SQRT(SUMSQ($F26:$I26)) -> 0.54856574 | E27: =I26/SQRT(SUMSQ($F26:$I26)) -> 0.49600197 | F27: =SUMPRODUCT($B$5:$E$5,$B27:$E27) -> -0.82891023 | G27: =SUMPRODUCT($B$6:$E$6,$B27:$E27) -> 1.3817048 | H27: =SUMPRODUCT($B$7:$E$7,$B27:$E27) -> 1.3131707 | I27: =SUMPRODUCT($B$8:$E$8,$B27:$E27) -> 1.18734 | J27: =SQRT(SUMXMY2(B27:E27,B26:E26)) -> 3.0548211e-06 | L27: =INDEX(L$5:L$20,$P27) -> Social infrastructure | M27: =INDEX(M$5:M$20,$P27) -> -0.0425459 | N27: =INDEX(N$5:N$20,$P27) -> -1.3787266 | O27: =INDEX(O$5:O$20,$P27) -> 1 | P27: =MOD(SMALL($P$5:$P$20,3),100) -> 3
A28: 16 | B28: =F27/SQRT(SUMSQ($F27:$I27)) -> -0.34627031 | C28: =G27/SQRT(SUMSQ($F27:$I27)) -> 0.57719563 | D28: =H27/SQRT(SUMSQ($F27:$I27)) -> 0.54856608 | E28: =I27/SQRT(SUMSQ($F27:$I27)) -> 0.49600134 | F28: =SUMPRODUCT($B$5:$E$5,$B28:$E28) -> -0.82891122 | G28: =SUMPRODUCT($B$6:$E$6,$B28:$E28) -> 1.3817045 | H28: =SUMPRODUCT($B$7:$E$7,$B28:$E28) -> 1.3131711 | I28: =SUMPRODUCT($B$8:$E$8,$B28:$E28) -> 1.1873393 | J28: =SQRT(SUMXMY2(B28:E28,B27:E27)) -> 1.2806114e-06 | L28: =INDEX(L$5:L$20,$P28) -> Nuclear | M28: =INDEX(M$5:M$20,$P28) -> 4.1101016 | N28: =INDEX(N$5:N$20,$P28) -> -1.0297504 | O28: =INDEX(O$5:O$20,$P28) -> 2 | P28: =MOD(SMALL($P$5:$P$20,4),100) -> 4
A29: 17 | B29: =F28/SQRT(SUMSQ($F28:$I28)) -> -0.34627073 | C29: =G28/SQRT(SUMSQ($F28:$I28)) -> 0.57719548 | D29: =H28/SQRT(SUMSQ($F28:$I28)) -> 0.54856622 | E29: =I28/SQRT(SUMSQ($F28:$I28)) -> 0.49600108 | F29: =SUMPRODUCT($B$5:$E$5,$B29:$E29) -> -0.82891164 | G29: =SUMPRODUCT($B$6:$E$6,$B29:$E29) -> 1.3817043 | H29: =SUMPRODUCT($B$7:$E$7,$B29:$E29) -> 1.3131712 | I29: =SUMPRODUCT($B$8:$E$8,$B29:$E29) -> 1.1873391 | J29: =SQRT(SUMXMY2(B29:E29,B28:E28)) -> 5.3684502e-07 | L29: =INDEX(L$5:L$20,$P29) -> Forestry | M29: =INDEX(M$5:M$20,$P29) -> 3.1864413 | N29: =INDEX(N$5:N$20,$P29) -> 0.27570459 | O29: =INDEX(O$5:O$20,$P29) -> 2 | P29: =MOD(SMALL($P$5:$P$20,5),100) -> 12
A30: 18 | B30: =F29/SQRT(SUMSQ($F29:$I29)) -> -0.3462709 | C30: =G29/SQRT(SUMSQ($F29:$I29)) -> 0.57719541 | D30: =H29/SQRT(SUMSQ($F29:$I29)) -> 0.54856628 | E30: =I29/SQRT(SUMSQ($F29:$I29)) -> 0.49600096 | F30: =SUMPRODUCT($B$5:$E$5,$B30:$E30) -> -0.82891181 | G30: =SUMPRODUCT($B$6:$E$6,$B30:$E30) -> 1.3817042 | H30: =SUMPRODUCT($B$7:$E$7,$B30:$E30) -> 1.3131713 | I30: =SUMPRODUCT($B$8:$E$8,$B30:$E30) -> 1.187339 | J30: =SQRT(SUMXMY2(B30:E30,B29:E29)) -> 2.2505077e-07 | L30: =INDEX(L$5:L$20,$P30) -> Defence | M30: =INDEX(M$5:M$20,$P30) -> 0.1865673 | N30: =INDEX(N$5:N$20,$P30) -> -0.53991745 | O30: =INDEX(O$5:O$20,$P30) -> 3 | P30: =MOD(SMALL($P$5:$P$20,6),100) -> 5
A31: 19 | B31: =F30/SQRT(SUMSQ($F30:$I30)) -> -0.34627097 | C31: =G30/SQRT(SUMSQ($F30:$I30)) -> 0.57719538 | D31: =H30/SQRT(SUMSQ($F30:$I30)) -> 0.54856631 | E31: =I30/SQRT(SUMSQ($F30:$I30)) -> 0.49600092 | F31: =SUMPRODUCT($B$5:$E$5,$B31:$E31) -> -0.82891189 | G31: =SUMPRODUCT($B$6:$E$6,$B31:$E31) -> 1.3817042 | H31: =SUMPRODUCT($B$7:$E$7,$B31:$E31) -> 1.3131713 | I31: =SUMPRODUCT($B$8:$E$8,$B31:$E31) -> 1.1873389 | J31: =SQRT(SUMXMY2(B31:E31,B30:E30)) -> 9.4343523e-08 | L31: =INDEX(L$5:L$20,$P31) -> Agriculture | M31: =INDEX(M$5:M$20,$P31) -> -0.017078677 | N31: =INDEX(N$5:N$20,$P31) -> -0.029864626 | O31: =INDEX(O$5:O$20,$P31) -> 3 | P31: =MOD(SMALL($P$5:$P$20,7),100) -> 6
A32: 20 | B32: =F31/SQRT(SUMSQ($F31:$I31)) -> -0.34627101 | C32: =G31/SQRT(SUMSQ($F31:$I31)) -> 0.57719537 | D32: =H31/SQRT(SUMSQ($F31:$I31)) -> 0.54856632 | E32: =I31/SQRT(SUMSQ($F31:$I31)) -> 0.4960009 | F32: =SUMPRODUCT($B$5:$E$5,$B32:$E32) -> -0.82891192 | G32: =SUMPRODUCT($B$6:$E$6,$B32:$E32) -> 1.3817042 | H32: =SUMPRODUCT($B$7:$E$7,$B32:$E32) -> 1.3131713 | I32: =SUMPRODUCT($B$8:$E$8,$B32:$E32) -> 1.1873389 | J32: =SQRT(SUMXMY2(B32:E32,B31:E31)) -> 3.9549743e-08 | L32: =INDEX(L$5:L$20,$P32) -> Manufacturing | M32: =INDEX(M$5:M$20,$P32) -> -0.67415705 | N32: =INDEX(N$5:N$20,$P32) -> -0.3018833 | O32: =INDEX(O$5:O$20,$P32) -> 3 | P32: =MOD(SMALL($P$5:$P$20,8),100) -> 7
A33: 21 | B33: =F32/SQRT(SUMSQ($F32:$I32)) -> -0.34627102 | C33: =G32/SQRT(SUMSQ($F32:$I32)) -> 0.57719537 | D33: =H32/SQRT(SUMSQ($F32:$I32)) -> 0.54856632 | E33: =I32/SQRT(SUMSQ($F32:$I32)) -> 0.49600089 | F33: =SUMPRODUCT($B$5:$E$5,$B33:$E33) -> -0.82891193 | G33: =SUMPRODUCT($B$6:$E$6,$B33:$E33) -> 1.3817042 | H33: =SUMPRODUCT($B$7:$E$7,$B33:$E33) -> 1.3131713 | I33: =SUMPRODUCT($B$8:$E$8,$B33:$E33) -> 1.1873389 | J33: =SQRT(SUMXMY2(B33:E33,B32:E32)) -> 1.6579646e-08 | L33: =INDEX(L$5:L$20,$P33) -> Financial services | M33: =INDEX(M$5:M$20,$P33) -> -0.82009863 | N33: =INDEX(N$5:N$20,$P33) -> 0.18024794 | O33: =INDEX(O$5:O$20,$P33) -> 3 | P33: =MOD(SMALL($P$5:$P$20,9),100) -> 8
A34: 22 | B34: =F33/SQRT(SUMSQ($F33:$I33)) -> -0.34627102 | C34: =G33/SQRT(SUMSQ($F33:$I33)) -> 0.57719536 | D34: =H33/SQRT(SUMSQ($F33:$I33)) -> 0.54856632 | E34: =I33/SQRT(SUMSQ($F33:$I33)) -> 0.49600089 | F34: =SUMPRODUCT($B$5:$E$5,$B34:$E34) -> -0.82891194 | G34: =SUMPRODUCT($B$6:$E$6,$B34:$E34) -> 1.3817042 | H34: =SUMPRODUCT($B$7:$E$7,$B34:$E34) -> 1.3131713 | I34: =SUMPRODUCT($B$8:$E$8,$B34:$E34) -> 1.1873389 | J34: =SQRT(SUMXMY2(B34:E34,B33:E33)) -> 6.9503524e-09 | L34: =INDEX(L$5:L$20,$P34) -> Gaming & entertainment | M34: =INDEX(M$5:M$20,$P34) -> -0.52763998 | N34: =INDEX(N$5:N$20,$P34) -> 0.19516423 | O34: =INDEX(O$5:O$20,$P34) -> 3 | P34: =MOD(SMALL($P$5:$P$20,10),100) -> 9
A35: 23 | B35: =F34/SQRT(SUMSQ($F34:$I34)) -> -0.34627103 | C35: =G34/SQRT(SUMSQ($F34:$I34)) -> 0.57719536 | D35: =H34/SQRT(SUMSQ($F34:$I34)) -> 0.54856632 | E35: =I34/SQRT(SUMSQ($F34:$I34)) -> 0.49600089 | F35: =SUMPRODUCT($B$5:$E$5,$B35:$E35) -> -0.82891194 | G35: =SUMPRODUCT($B$6:$E$6,$B35:$E35) -> 1.3817042 | H35: =SUMPRODUCT($B$7:$E$7,$B35:$E35) -> 1.3131713 | I35: =SUMPRODUCT($B$8:$E$8,$B35:$E35) -> 1.1873389 | J35: =SQRT(SUMXMY2(B35:E35,B34:E34)) -> 2.9136569e-09 | L35: =INDEX(L$5:L$20,$P35) -> Chemicals & pharmaceuticals | M35: =INDEX(M$5:M$20,$P35) -> -0.73589401 | N35: =INDEX(N$5:N$20,$P35) -> 0.87689066 | O35: =INDEX(O$5:O$20,$P35) -> 3 | P35: =MOD(SMALL($P$5:$P$20,11),100) -> 10
A36: 24 | B36: =F35/SQRT(SUMSQ($F35:$I35)) -> -0.34627103 | C36: =G35/SQRT(SUMSQ($F35:$I35)) -> 0.57719536 | D36: =H35/SQRT(SUMSQ($F35:$I35)) -> 0.54856632 | E36: =I35/SQRT(SUMSQ($F35:$I35)) -> 0.49600089 | F36: =SUMPRODUCT($B$5:$E$5,$B36:$E36) -> -0.82891194 | G36: =SUMPRODUCT($B$6:$E$6,$B36:$E36) -> 1.3817042 | H36: =SUMPRODUCT($B$7:$E$7,$B36:$E36) -> 1.3131713 | I36: =SUMPRODUCT($B$8:$E$8,$B36:$E36) -> 1.1873389 | J36: =SQRT(SUMXMY2(B36:E36,B35:E35)) -> 1.2214339e-09 | L36: =INDEX(L$5:L$20,$P36) -> Renewables | M36: =INDEX(M$5:M$20,$P36) -> 0.7011835 | N36: =INDEX(N$5:N$20,$P36) -> 1.166668 | O36: =INDEX(O$5:O$20,$P36) -> 3 | P36: =MOD(SMALL($P$5:$P$20,12),100) -> 11
A37: 25 | B37: =F36/SQRT(SUMSQ($F36:$I36)) -> -0.34627103 | C37: =G36/SQRT(SUMSQ($F36:$I36)) -> 0.57719536 | D37: =H36/SQRT(SUMSQ($F36:$I36)) -> 0.54856632 | E37: =I36/SQRT(SUMSQ($F36:$I36)) -> 0.49600089 | F37: =SUMPRODUCT($B$5:$E$5,$B37:$E37) -> -0.82891194 | G37: =SUMPRODUCT($B$6:$E$6,$B37:$E37) -> 1.3817042 | H37: =SUMPRODUCT($B$7:$E$7,$B37:$E37) -> 1.3131713 | I37: =SUMPRODUCT($B$8:$E$8,$B37:$E37) -> 1.1873389 | J37: =SQRT(SUMXMY2(B37:E37,B36:E36)) -> 5.1203727e-10 | L37: =INDEX(L$5:L$20,$P37) -> Transport | M37: =INDEX(M$5:M$20,$P37) -> -0.37985929 | N37: =INDEX(N$5:N$20,$P37) -> 1.0774228 | O37: =INDEX(O$5:O$20,$P37) -> 3 | P37: =MOD(SMALL($P$5:$P$20,13),100) -> 13
A38: 26 | B38: =F37/SQRT(SUMSQ($F37:$I37)) -> -0.34627103 | C38: =G37/SQRT(SUMSQ($F37:$I37)) -> 0.57719536 | D38: =H37/SQRT(SUMSQ($F37:$I37)) -> 0.54856632 | E38: =I37/SQRT(SUMSQ($F37:$I37)) -> 0.49600088 | F38: =SUMPRODUCT($B$5:$E$5,$B38:$E38) -> -0.82891194 | G38: =SUMPRODUCT($B$6:$E$6,$B38:$E38) -> 1.3817042 | H38: =SUMPRODUCT($B$7:$E$7,$B38:$E38) -> 1.3131713 | I38: =SUMPRODUCT($B$8:$E$8,$B38:$E38) -> 1.1873389 | J38: =SQRT(SUMXMY2(B38:E38,B37:E37)) -> 2.1465109e-10 | L38: =INDEX(L$5:L$20,$P38) -> Technology | M38: =INDEX(M$5:M$20,$P38) -> -0.38842448 | N38: =INDEX(N$5:N$20,$P38) -> 1.1835452 | O38: =INDEX(O$5:O$20,$P38) -> 3 | P38: =MOD(SMALL($P$5:$P$20,14),100) -> 14
A39: 27 | B39: =F38/SQRT(SUMSQ($F38:$I38)) -> -0.34627103 | C39: =G38/SQRT(SUMSQ($F38:$I38)) -> 0.57719536 | D39: =H38/SQRT(SUMSQ($F38:$I38)) -> 0.54856632 | E39: =I38/SQRT(SUMSQ($F38:$I38)) -> 0.49600088 | F39: =SUMPRODUCT($B$5:$E$5,$B39:$E39) -> -0.82891194 | G39: =SUMPRODUCT($B$6:$E$6,$B39:$E39) -> 1.3817042 | H39: =SUMPRODUCT($B$7:$E$7,$B39:$E39) -> 1.3131713 | I39: =SUMPRODUCT($B$8:$E$8,$B39:$E39) -> 1.1873389 | J39: =SQRT(SUMXMY2(B39:E39,B38:E38)) -> 8.9983915e-11 | L39: =INDEX(L$5:L$20,$P39) -> Infrastructure | M39: =INDEX(M$5:M$20,$P39) -> -0.47827924 | N39: =INDEX(N$5:N$20,$P39) -> 1.5450487 | O39: =INDEX(O$5:O$20,$P39) -> 3 | P39: =MOD(SMALL($P$5:$P$20,15),100) -> 15
A40: 28 | B40: =F39/SQRT(SUMSQ($F39:$I39)) -> -0.34627103 | C40: =G39/SQRT(SUMSQ($F39:$I39)) -> 0.57719536 | D40: =H39/SQRT(SUMSQ($F39:$I39)) -> 0.54856632 | E40: =I39/SQRT(SUMSQ($F39:$I39)) -> 0.49600088 | F40: =SUMPRODUCT($B$5:$E$5,$B40:$E40) -> -0.82891194 | G40: =SUMPRODUCT($B$6:$E$6,$B40:$E40) -> 1.3817042 | H40: =SUMPRODUCT($B$7:$E$7,$B40:$E40) -> 1.3131713 | I40: =SUMPRODUCT($B$8:$E$8,$B40:$E40) -> 1.1873389 | J40: =SQRT(SUMXMY2(B40:E40,B39:E39)) -> 3.772217e-11 | L40: =INDEX(L$5:L$20,$P40) -> Other | M40: =INDEX(M$5:M$20,$P40) -> -1.008714 | N40: =INDEX(N$5:N$20,$P40) -> -0.26137643 | O40: =INDEX(O$5:O$20,$P40) -> 3 | P40: =MOD(SMALL($P$5:$P$20,16),100) -> 16
...

Sheet KMeans
A1: Step 3: K-means clustering (k = 3) on the standardised features
A2: Each iteration: distance of every sector to the 3 cluster centres, assign to nearest, recompute cluster centres as cluster means (cluster centre tables below).
G4: Iteration 0 | K4: Iteration 1 | O4: Iteration 2 | S4: Iteration 3 | W4: Iteration 4 | AA4: Iteration 5 | AE4: Iteration 6 | AI4: Iteration 7
A5: Sector | B5: z: ln(avg volume) | C5: z: YoY growth FY24 | D5: z: Volatility (CV) | E5: z: Relative trend | F5: Final cluster | G5: d to C1 | H5: d to C2 | I5: d to C3 | J5: Cluster | K5: d to C1 | L5: d to C2 | M5: d to C3 | N5: Cluster | O5: d to C1 | P5: d to C2 | Q5: d to C3 | R5: Cluster | S5: d to C1 | T5: d to C2 | U5: d to C3 | V5: Cluster | W5: d to C1 | X5: d to C2 | Y5: d to C3 | Z5: Cluster | AA5: d to C1 | AB5: d to C2 | AC5: d to C3 | AD5: Cluster | AE5: d to C1 | AF5: d to C2 | AG5: d to C3 | AH5: Cluster | AI5: d to C1 | AJ5: d to C2 | AK5: d to C3 | AL5: Cluster | AM5: Dist to own cluster centre
A6: =Features!A6 -> Mining | B6: =Features!I6 -> 2.2282166 | C6: =Features!J6 -> -0.72394527 | D6: =Features!K6 -> -0.19392696 | E6: =Features!L6 -> -0.44607581 | F6: =AL6 -> 1 | G6: =SQRT(SUMXMY2($B6:$E6,$B28:$E28)) -> 0 | H6: =SQRT(SUMXMY2($B6:$E6,$B29:$E29)) -> 5.7422462 | I6: =SQRT(SUMXMY2($B6:$E6,$B30:$E30)) -> 3.0386174 | J6: =MATCH(MIN(G6:I6),G6:I6,0) -> 1 | K6: =SQRT(SUMXMY2($B6:$E6,$B33:$E33)) -> 0.96280949 | L6: =SQRT(SUMXMY2($B6:$E6,$B34:$E34)) -> 5.377233 | M6: =SQRT(SUMXMY2($B6:$E6,$B35:$E35)) -> 2.5650793 | N6: =MATCH(MIN(K6:M6),K6:M6,0) -> 1 | O6: =SQRT(SUMXMY2($B6:$E6,$B38:$E38)) -> 0.96280949 | P6: =SQRT(SUMXMY2($B6:$E6,$B39:$E39)) -> 5.377233 | Q6: =SQRT(SUMXMY2($B6:$E6,$B40:$E40)) -> 2.5650793 | R6: =MATCH(MIN(O6:Q6),O6:Q6,0) -> 1 | S6: =SQRT(SUMXMY2($B6:$E6,$B43:$E43)) -> 0.96280949 | T6: =SQRT(SUMXMY2($B6:$E6,$B44:$E44)) -> 5.377233 | U6: =SQRT(SUMXMY2($B6:$E6,$B45:$E45)) -> 2.5650793 | V6: =MATCH(MIN(S6:U6),S6:U6,0) -> 1 | W6: =SQRT(SUMXMY2($B6:$E6,$B48:$E48)) -> 0.96280949 | X6: =SQRT(SUMXMY2($B6:$E6,$B49:$E49)) -> 5.377233 | Y6: =SQRT(SUMXMY2($B6:$E6,$B50:$E50)) -> 2.5650793 | Z6: =MATCH(MIN(W6:Y6),W6:Y6,0) -> 1 | AA6: =SQRT(SUMXMY2($B6:$E6,$B53:$E53)) -> 0.96280949 | AB6: =SQRT(SUMXMY2($B6:$E6,$B54:$E54)) -> 5.377233 | AC6: =SQRT(SUMXMY2($B6:$E6,$B55:$E55)) -> 2.5650793 | AD6: =MATCH(MIN(AA6:AC6),AA6:AC6,0) -> 1 | AE6: =SQRT(SUMXMY2($B6:$E6,$B58:$E58)) -> 0.96280949 | AF6: =SQRT(SUMXMY2($B6:$E6,$B59:$E59)) -> 5.377233 | AG6: =SQRT(SUMXMY2($B6:$E6,$B60:$E60)) -> 2.5650793 | AH6: =MATCH(MIN(AE6:AG6),AE6:AG6,0) -> 1 | AI6: =SQRT(SUMXMY2($B6:$E6,$B63:$E63)) -> 0.96280949 | AJ6: =SQRT(SUMXMY2($B6:$E6,$B64:$E64)) -> 5.377233 | AK6: =SQRT(SUMXMY2($B6:$E6,$B65:$E65)) -> 2.5650793 | AL6: =MATCH(MIN(AI6:AK6),AI6:AK6,0) -> 1 | AM6: =INDEX(AI6:AK6,AL6) -> 0.96280949
A7: =Features!A7 -> Energy | B7: =Features!I7 -> 2.0162355 | C7: =Features!J7 -> -0.34335418 | D7: =Features!K7 -> -1.0432511 | E7: =Features!L7 -> -0.25383652 | F7: =AL7 -> 1 | G7: =SQRT(SUMXMY2($B7:$E7,$B28:$E28)) -> 0.97370062 | H7: =SQRT(SUMXMY2($B7:$E7,$B29:$E29)) -> 5.7556104 | I7: =SQRT(SUMXMY2($B7:$E7,$B30:$E30)) -> 3.0623542 | J7: =MATCH(MIN(G7:I7),G7:I7,0) -> 1 | K7: =SQRT(SUMXMY2($B7:$E7,$B33:$E33)) -> 0.58874148 | L7: =SQRT(SUMXMY2($B7:$E7,$B34:$E34)) -> 5.4081501 | M7: =SQRT(SUMXMY2($B7:$E7,$B35:$E35)) -> 2.4719236 | N7: =MATCH(MIN(K7:M7),K7:M7,0) -> 1 | O7: =SQRT(SUMXMY2($B7:$E7,$B38:$E38)) -> 0.58874148 | P7: =SQRT(SUMXMY2($B7:$E7,$B39:$E39)) -> 5.4081501 | Q7: =SQRT(SUMXMY2($B7:$E7,$B40:$E40)) -> 2.4719236 | R7: =MATCH(MIN(O7:Q7),O7:Q7,0) -> 1 | S7: =SQRT(SUMXMY2($B7:$E7,$B43:$E43)) -> 0.58874148 | T7: =SQRT(SUMXMY2($B7:$E7,$B44:$E44)) -> 5.4081501 | U7: =SQRT(SUMXMY2($B7:$E7,$B45:$E45)) -> 2.4719236 | V7: =MATCH(MIN(S7:U7),S7:U7,0) -> 1 | W7: =SQRT(SUMXMY2($B7:$E7,$B48:$E48)) -> 0.58874148 | X7: =SQRT(SUMXMY2($B7:$E7,$B49:$E49)) -> 5.4081501 | Y7: =SQRT(SUMXMY2($B7:$E7,$B50:$E50)) -> 2.4719236 | Z7: =MATCH(MIN(W7:Y7),W7:Y7,0) -> 1 | AA7: =SQRT(SUMXMY2($B7:$E7,$B53:$E53)) -> 0.58874148 | AB7: =SQRT(SUMXMY2($B7:$E7,$B54:$E54)) -> 5.4081501 | AC7: =SQRT(SUMXMY2($B7:$E7,$B55:$E55)) -> 2.4719236 | AD7: =MATCH(MIN(AA7:AC7),AA7:AC7,0) -> 1 | AE7: =SQRT(SUMXMY2($B7:$E7,$B58:$E58)) -> 0.58874148 | AF7: =SQRT(SUMXMY2($B7:$E7,$B59:$E59)) -> 5.4081501 | AG7: =SQRT(SUMXMY2($B7:$E7,$B60:$E60)) -> 2.4719236 | AH7: =MATCH(MIN(AE7:AG7),AE7:AG7,0) -> 1 | AI7: =SQRT(SUMXMY2($B7:$E7,$B63:$E63)) -> 0.58874148 | AJ7: =SQRT(SUMXMY2($B7:$E7,$B64:$E64)) -> 5.4081501 | AK7: =SQRT(SUMXMY2($B7:$E7,$B65:$E65)) -> 2.4719236 | AL7: =MATCH(MIN(AI7:AK7),AI7:AK7,0) -> 1 | AM7: =INDEX(AI7:AK7,AL7) -> 0.58874148
A8: =Features!A8 -> Social infrastructure | B8: =Features!I8 -> 0.9234591 | C8: =Features!J8 -> 0.48894622 | D8: =Features!K8 -> -0.64722817 | E8: =Features!L8 -> 0.70574737 | F8: =AL8 -> 1 | G8: =SQRT(SUMXMY2($B8:$E8,$B28:$E28)) -> 2.1692571 | H8: =SQRT(SUMXMY2($B8:$E8,$B29:$E29)) -> 4.2872111 | I8: =SQRT(SUMXMY2($B8:$E8,$B30:$E30)) -> 2.6236998 | J8: =MATCH(MIN(G8:I8),G8:I8,0) -> 1 | K8: =SQRT(SUMXMY2($B8:$E8,$B33:$E33)) -> 1.2645728 | L8: =SQRT(SUMXMY2($B8:$E8,$B34:$E34)) -> 3.861511 | M8: =SQRT(SUMXMY2($B8:$E8,$B35:$E35)) -> 1.8804576 | N8: =MATCH(MIN(K8:M8),K8:M8,0) -> 1 | O8: =SQRT(SUMXMY2($B8:$E8,$B38:$E38)) -> 1.2645728 | P8: =SQRT(SUMXMY2($B8:$E8,$B39:$E39)) -> 3.861511 | Q8: =SQRT(SUMXMY2($B8:$E8,$B40:$E40)) -> 1.8804576 | R8: =MATCH(MIN(O8:Q8),O8:Q8,0) -> 1 | S8: =SQRT(SUMXMY2($B8:$E8,$B43:$E43)) -> 1.2645728 | T8: =SQRT(SUMXMY2($B8:$E8,$B44:$E44)) -> 3.861511 | U8: =SQRT(SUMXMY2($B8:$E8,$B45:$E45)) -> 1.8804576 | V8: =MATCH(MIN(S8:U8),S8:U8,0) -> 1 | W8: =SQRT(SUMXMY2($B8:$E8,$B48:$E48)) -> 1.2645728 | X8: =SQRT(SUMXMY2($B8:$E8,$B49:$E49)) -> 3.861511 | Y8: =SQRT(SUMXMY2($B8:$E8,$B50:$E50)) -> 1.8804576 | Z8: =MATCH(MIN(W8:Y8),W8:Y8,0) -> 1 | AA8: =SQRT(SUMXMY2($B8:$E8,$B53:$E53)) -> 1.2645728 | AB8: =SQRT(SUMXMY2($B8:$E8,$B54:$E54)) -> 3.861511 | AC8: =SQRT(SUMXMY2($B8:$E8,$B55:$E55)) -> 1.8804576 | AD8: =MATCH(MIN(AA8:AC8),AA8:AC8,0) -> 1 | AE8: =SQRT(SUMXMY2($B8:$E8,$B58:$E58)) -> 1.2645728 | AF8: =SQRT(SUMXMY2($B8:$E8,$B59:$E59)) -> 3.861511 | AG8: =SQRT(SUMXMY2($B8:$E8,$B60:$E60)) -> 1.8804576 | AH8: =MATCH(MIN(AE8:AG8),AE8:AG8,0) -> 1 | AI8: =SQRT(SUMXMY2($B8:$E8,$B63:$E63)) -> 1.2645728 | AJ8: =SQRT(SUMXMY2($B8:$E8,$B64:$E64)) -> 3.861511 | AK8: =SQRT(SUMXMY2($B8:$E8,$B65:$E65)) -> 1.8804576 | AL8: =MATCH(MIN(AI8:AK8),AI8:AK8,0) -> 1 | AM8: =INDEX(AI8:AK8,AL8) -> 1.2645728
A9: =Features!A9 -> Nuclear | B9: =Features!I9 -> -0.32495391 | C9: =Features!J9 -> 3.1232857 | D9: =Features!K9 -> 2.2411376 | E9: =Features!L9 -> 1.9464095 | F9: =AL9 -> 2 | G9: =SQRT(SUMXMY2($B9:$E9,$B28:$E28)) -> 5.7422462 | H9: =SQRT(SUMXMY2($B9:$E9,$B29:$E29)) -> 0 | I9: =SQRT(SUMXMY2($B9:$E9,$B30:$E30)) -> 5.0457921 | J9: =MATCH(MIN(G9:I9),G9:I9,0) -> 2 | K9: =SQRT(SUMXMY2($B9:$E9,$B33:$E33)) -> 5.215613 | L9: =SQRT(SUMXMY2($B9:$E9,$B34:$E34)) -> 1.2517852 | M9: =SQRT(SUMXMY2($B9:$E9,$B35:$E35)) -> 4.8183523 | N9: =MATCH(MIN(K9:M9),K9:M9,0) -> 2 | O9: =SQRT(SUMXMY2($B9:$E9,$B38:$E38)) -> 5.215613 | P9: =SQRT(SUMXMY2($B9:$E9,$B39:$E39)) -> 1.2517852 | Q9: =SQRT(SUMXMY2($B9:$E9,$B40:$E40)) -> 4.8183523 | R9: =MATCH(MIN(O9:Q9),O9:Q9,0) -> 2 | S9: =SQRT(SUMXMY2($B9:$E9,$B43:$E43)) -> 5.215613 | T9: =SQRT(SUMXMY2($B9:$E9,$B44:$E44)) -> 1.2517852 | U9: =SQRT(SUMXMY2($B9:$E9,$B45:$E45)) -> 4.8183523 | V9: =MATCH(MIN(S9:U9),S9:U9,0) -> 2 | W9: =SQRT(SUMXMY2($B9:$E9,$B48:$E48)) -> 5.215613 | X9: =SQRT(SUMXMY2($B9:$E9,$B49:$E49)) -> 1.2517852 | Y9: =SQRT(SUMXMY2($B9:$E9,$B50:$E50)) -> 4.8183523 | Z9: =MATCH(MIN(W9:Y9),W9:Y9,0) -> 2 | AA9: =SQRT(SUMXMY2($B9:$E9,$B53:$E53)) -> 5.215613 | AB9: =SQRT(SUMXMY2($B9:$E9,$B54:$E54)) -> 1.2517852 | AC9: =SQRT(SUMXMY2($B9:$E9,$B55:$E55)) -> 4.8183523 | AD9: =MATCH(MIN(AA9:AC9),AA9:AC9,0) -> 2 | AE9: =SQRT(SUMXMY2($B9:$E9,$B58:$E58)) -> 5.215613 | AF9: =SQRT(SUMXMY2($B9:$E9,$B59:$E59)) -> 1.2517852 | AG9: =SQRT(SUMXMY2($B9:$E9,$B60:$E60)) -> 4.8183523 | AH9: =MATCH(MIN(AE9:AG9),AE9:AG9,0) -> 2 | AI9: =SQRT(SUMXMY2($B9:$E9,$B63:$E63)) -> 5.215613 | AJ9: =SQRT(SUMXMY2($B9:$E9,$B64:$E64)) -> 1.2517852 | AK9: =SQRT(SUMXMY2($B9:$E9,$B65:$E65)) -> 4.8183523 | AL9: =MATCH(MIN(AI9:AK9),AI9:AK9,0) -> 2 | AM9: =INDEX(AI9:AK9,AL9) -> 1.2517852
A10: =Features!A10 -> Defence | B10: =Features!I10 -> -0.13549729 | C10: =Features!J10 -> 0.42412651 | D10: =Features!K10 -> -0.77106832 | E10: =Features!L10 -> 0.64077863 | F10: =AL10 -> 3 | G10: =SQRT(SUMXMY2($B10:$E10,$B28:$E28)) -> 2.9016472 | H10: =SQRT(SUMXMY2($B10:$E10,$B29:$E29)) -> 4.2543402 | I10: =SQRT(SUMXMY2($B10:$E10,$B30:$E30)) -> 2.0972373 | J10: =MATCH(MIN(G10:I10),G10:I10,0) -> 3 | K10: =SQRT(SUMXMY2($B10:$E10,$B33:$E33)) -> 2.0644081 | L10: =SQRT(SUMXMY2($B10:$E10,$B34:$E34)) -> 3.6350346 | M10: =SQRT(SUMXMY2($B10:$E10,$B35:$E35)) -> 1.3953795 | N10: =MATCH(MIN(K10:M10),K10:M10,0) -> 3 | O10: =SQRT(SUMXMY2($B10:$E10,$B38:$E38)) -> 2.0644081 | P10: =SQRT(SUMXMY2($B10:$E10,$B39:$E39)) -> 3.6350346 | Q10: =SQRT(SUMXMY2($B10:$E10,$B40:$E40)) -> 1.3953795 | R10: =MATCH(MIN(O10:Q10),O10:Q10,0) -> 3 | S10: =SQRT(SUMXMY2($B10:$E10,$B43:$E43)) -> 2.0644081 | T10: =SQRT(SUMXMY2($B10:$E10,$B44:$E44)) -> 3.6350346 | U10: =SQRT(SUMXMY2($B10:$E10,$B45:$E45)) -> 1.3953795 | V10: =MATCH(MIN(S10:U10),S10:U10,0) -> 3 | W10: =SQRT(SUMXMY2($B10:$E10,$B48:$E48)) -> 2.0644081 | X10: =SQRT(SUMXMY2($B10:$E10,$B49:$E49)) -> 3.6350346 | Y10: =SQRT(SUMXMY2($B10:$E10,$B50:$E50)) -> 1.3953795 | Z10: =MATCH(MIN(W10:Y10),W10:Y10,0) -> 3 | AA10: =SQRT(SUMXMY2($B10:$E10,$B53:$E53)) -> 2.0644081 | AB10: =SQRT(SUMXMY2($B10:$E10,$B54:$E54)) -> 3.6350346 | AC10: =SQRT(SUMXMY2($B10:$E10,$B55:$E55)) -> 1.3953795 | AD10: =MATCH(MIN(AA10:AC10),AA10:AC10,0) -> 3 | AE10: =SQRT(SUMXMY2($B10:$E10,$B58:$E58)) -> 2.0644081 | AF10: =SQRT(SUMXMY2($B10:$E10,$B59:$E59)) -> 3.6350346 | AG10: =SQRT(SUMXMY2($B10:$E10,$B60:$E60)) -> 1.3953795 | AH10: =MATCH(MIN(AE10:AG10),AE10:AG10,0) -> 3 | AI10: =SQRT(SUMXMY2($B10:$E10,$B63:$E63)) -> 2.0644081 | AJ10: =SQRT(SUMXMY2($B10:$E10,$B64:$E64)) -> 3.6350346 | AK10: =SQRT(SUMXMY2($B10:$E10,$B65:$E65)) -> 1.3953795 | AL10: =MATCH(MIN(AI10:AK10),AI10:AK10,0) -> 3 | AM10: =INDEX(AI10:AK10,AL10) -> 1.3953795
A11: =Features!A11 -> Agriculture | B11: =Features!I11 -> -0.0914719 | C11: =Features!J11 -> -0.47960981 | D11: =Features!K11 -> -0.018507391 | E11: =Features!L11 -> 0.48029823 | F11: =AL11 -> 3 | G11: =SQRT(SUMXMY2($B11:$E11,$B28:$E28)) -> 2.5158687 | H11: =SQRT(SUMXMY2($B11:$E11,$B29:$E29)) -> 4.5045363 | I11: =SQRT(SUMXMY2($B11:$E11,$B30:$E30)) -> 1.6109002 | J11: =MATCH(MIN(G11:I11),G11:I11,0) -> 3 | K11: =SQRT(SUMXMY2($B11:$E11,$B33:$E33)) -> 1.9934212 | L11: =SQRT(SUMXMY2($B11:$E11,$B34:$E34)) -> 3.7218209 | M11: =SQRT(SUMXMY2($B11:$E11,$B35:$E35)) -> 0.91759047 | N11: =MATCH(MIN(K11:M11),K11:M11,0) -> 3 | O11: =SQRT(SUMXMY2($B11:$E11,$B38:$E38)) -> 1.9934212 | P11: =SQRT(SUMXMY2($B11:$E11,$B39:$E39)) -> 3.7218209 | Q11: =SQRT(SUMXMY2($B11:$E11,$B40:$E40)) -> 0.91759047 | R11: =MATCH(MIN(O11:Q11),O11:Q11,0) -> 3 | S11: =SQRT(SUMXMY2($B11:$E11,$B43:$E43)) -> 1.9934212 | T11: =SQRT(SUMXMY2($B11:$E11,$B44:$E44)) -> 3.7218209 | U11: =SQRT(SUMXMY2($B11:$E11,$B45:$E45)) -> 0.91759047 | V11: =MATCH(MIN(S11:U11),S11:U11,0) -> 3 | W11: =SQRT(SUMXMY2($B11:$E11,$B48:$E48)) -> 1.9934212 | X11: =SQRT(SUMXMY2($B11:$E11,$B49:$E49)) -> 3.7218209 | Y11: =SQRT(SUMXMY2($B11:$E11,$B50:$E50)) -> 0.91759047 | Z11: =MATCH(MIN(W11:Y11),W11:Y11,0) -> 3 | AA11: =SQRT(SUMXMY2($B11:$E11,$B53:$E53)) -> 1.9934212 | AB11: =SQRT(SUMXMY2($B11:$E11,$B54:$E54)) -> 3.7218209 | AC11: =SQRT(SUMXMY2($B11:$E11,$B55:$E55)) -> 0.91759047 | AD11: =MATCH(MIN(AA11:AC11),AA11:AC11,0) -> 3 | AE11: =SQRT(SUMXMY2($B11:$E11,$B58:$E58)) -> 1.9934212 | AF11: =SQRT(SUMXMY2($B11:$E11,$B59:$E59)) -> 3.7218209 | AG11: =SQRT(SUMXMY2($B11:$E11,$B60:$E60)) -> 0.91759047 | AH11: =MATCH(MIN(AE11:AG11),AE11:AG11,0) -> 3 | AI11: =SQRT(SUMXMY2($B11:$E11,$B63:$E63)) -> 1.9934212 | AJ11: =SQRT(SUMXMY2($B11:$E11,$B64:$E64)) -> 3.7218209 | AK11: =SQRT(SUMXMY2($B11:$E11,$B65:$E65)) -> 0.91759047 | AL11: =MATCH(MIN(AI11:AK11),AI11:AK11,0) -> 3 | AM11: =INDEX(AI11:AK11,AL11) -> 0.91759047
A12: =Features!A12 -> Manufacturing | B12: =Features!I12 -> -0.18078072 | C12: =Features!J12 -> -0.10004056 | D12: =Features!K12 -> -1.4141162 | E12: =Features!L12 -> 0.19500633 | F12: =AL12 -> 3 | G12: =SQRT(SUMXMY2($B12:$E12,$B28:$E28)) -> 2.8447097 | H12: =SQRT(SUMXMY2($B12:$E12,$B29:$E29)) -> 5.1806285 | I12: =SQRT(SUMXMY2($B12:$E12,$B30:$E30)) -> 2.0225402 | J12: =MATCH(MIN(G12:I12),G12:I12,0) -> 3 | K12: =SQRT(SUMXMY2($B12:$E12,$B33:$E33)) -> 2.0704201 | L12: =SQRT(SUMXMY2($B12:$E12,$B34:$E34)) -> 4.5422377 | M12: =SQRT(SUMXMY2($B12:$E12,$B35:$E35)) -> 1.36646 | N12: =MATCH(MIN(K12:M12),K12:M12,0) -> 3 | O12: =SQRT(SUMXMY2($B12:$E12,$B38:$E38)) -> 2.0704201 | P12: =SQRT(SUMXMY2($B12:$E12,$B39:$E39)) -> 4.5422377 | Q12: =SQRT(SUMXMY2($B12:$E12,$B40:$E40)) -> 1.36646 | R12: =MATCH(MIN(O12:Q12),O12:Q12,0) -> 3 | S12: =SQRT(SUMXMY2($B12:$E12,$B43:$E43)) -> 2.0704201 | T12: =SQRT(SUMXMY2($B12:$E12,$B44:$E44)) -> 4.5422377 | U12: =SQRT(SUMXMY2($B12:$E12,$B45:$E45)) -> 1.36646 | V12: =MATCH(MIN(S12:U12),S12:U12,0) -> 3 | W12: =SQRT(SUMXMY2($B12:$E12,$B48:$E48)) -> 2.0704201 | X12: =SQRT(SUMXMY2($B12:$E12,$B49:$E49)) -> 4.5422377 | Y12: =SQRT(SUMXMY2($B12:$E12,$B50:$E50)) -> 1.36646 | Z12: =MATCH(MIN(W12:Y12),W12:Y12,0) -> 3 | AA12: =SQRT(SUMXMY2($B12:$E12,$B53:$E53)) -> 2.0704201 | AB12: =SQRT(SUMXMY2($B12:$E12,$B54:$E54)) -> 4.5422377 | AC12: =SQRT(SUMXMY2($B12:$E12,$B55:$E55)) -> 1.36646 | AD12: =MATCH(MIN(AA12:AC12),AA12:AC12,0) -> 3 | AE12: =SQRT(SUMXMY2($B12:$E12,$B58:$E58)) -> 2.0704201 | AF12: =SQRT(SUMXMY2($B12:$E12,$B59:$E59)) -> 4.5422377 | AG12: =SQRT(SUMXMY2($B12:$E12,$B60:$E60)) -> 1.36646 | AH12: =MATCH(MIN(AE12:AG12),AE12:AG12,0) -> 3 | AI12: =SQRT(SUMXMY2($B12:$E12,$B63:$E63)) -> 2.0704201 | AJ12: =SQRT(SUMXMY2($B12:$E12,$B64:$E64)) -> 4.5422377 | AK12: =SQRT(SUMXMY2($B12:$E12,$B65:$E65)) -> 1.36646 | AL12: =MATCH(MIN(AI12:AK12),AI12:AK12,0) -> 3 | AM12: =INDEX(AI12:AK12,AL12) -> 1.36646
A13: =Features!A13 -> Financial services | B13: =Features!I13 -> 0.0337099 | C13: =Features!J13 -> -0.58805817 | D13: =Features!K13 -> -0.53341738 | E13: =Features!L13 -> -0.35561753 | F13: =AL13 -> 3 | G13: =SQRT(SUMXMY2($B13:$E13,$B28:$E28)) -> 2.2266031 | H13: =SQRT(SUMXMY2($B13:$E13,$B29:$E29)) -> 5.18654 | I13: =SQRT(SUMXMY2($B13:$E13,$B30:$E30)) -> 1.2011418 | J13: =MATCH(MIN(G13:I13),G13:I13,0) -> 3 | K13: =SQRT(SUMXMY2($B13:$E13,$B33:$E33)) -> 1.7735667 | L13: =SQRT(SUMXMY2($B13:$E13,$B34:$E34)) -> 4.5159566 | M13: =SQRT(SUMXMY2($B13:$E13,$B35:$E35)) -> 0.54596361 | N13: =MATCH(MIN(K13:M13),K13:M13,0) -> 3 | O13: =SQRT(SUMXMY2($B13:$E13,$B38:$E38)) -> 1.7735667 | P13: =SQRT(SUMXMY2($B13:$E13,$B39:$E39)) -> 4.5159566 | Q13: =SQRT(SUMXMY2($B13:$E13,$B40:$E40)) -> 0.54596361 | R13: =MATCH(MIN(O13:Q13),O13:Q13,0) -> 3 | S13: =SQRT(SUMXMY2($B13:$E13,$B43:$E43)) -> 1.7735667 | T13: =SQRT(SUMXMY2($B13:$E13,$B44:$E44)) -> 4.5159566 | U13: =SQRT(SUMXMY2($B13:$E13,$B45:$E45)) -> 0.54596361 | V13: =MATCH(MIN(S13:U13),S13:U13,0) -> 3 | W13: =SQRT(SUMXMY2($B13:$E13,$B48:$E48)) -> 1.7735667 | X13: =SQRT(SUMXMY2($B13:$E13,$B49:$E49)) -> 4.5159566 | Y13: =SQRT(SUMXMY2($B13:$E13,$B50:$E50)) -> 0.54596361 | Z13: =MATCH(MIN(W13:Y13),W13:Y13,0) -> 3 | AA13: =SQRT(SUMXMY2($B13:$E13,$B53:$E53)) -> 1.7735667 | AB13: =SQRT(SUMXMY2($B13:$E13,$B54:$E54)) -> 4.5159566 | AC13: =SQRT(SUMXMY2($B13:$E13,$B55:$E55)) -> 0.54596361 | AD13: =MATCH(MIN(AA13:AC13),AA13:AC13,0) -> 3 | AE13: =SQRT(SUMXMY2($B13:$E13,$B58:$E58)) -> 1.7735667 | AF13: =SQRT(SUMXMY2($B13:$E13,$B59:$E59)) -> 4.5159566 | AG13: =SQRT(SUMXMY2($B13:$E13,$B60:$E60)) -> 0.54596361 | AH13: =MATCH(MIN(AE13:AG13),AE13:AG13,0) -> 3 | AI13: =SQRT(SUMXMY2($B13:$E13,$B63:$E63)) -> 1.7735667 | AJ13: =SQRT(SUMXMY2($B13:$E13,$B64:$E64)) -> 4.5159566 | AK13: =SQRT(SUMXMY2($B13:$E13,$B65:$E65)) -> 0.54596361 | AL13: =MATCH(MIN(AI13:AK13),AI13:AK13,0) -> 3 | AM13: =INDEX(AI13:AK13,AL13) -> 0.54596361
A14: =Features!A14 -> Gaming & entertainment | B14: =Features!I14 -> -0.21561316 | C14: =Features!J14 -> -0.54167774 | D14: =Features!K14 -> -0.51674174 | E14: =Features!L14 -> -0.012458812 | F14: =AL14 -> 3 | G14: =SQRT(SUMXMY2($B14:$E14,$B28:$E28)) -> 2.5095335 | H14: =SQRT(SUMXMY2($B14:$E14,$B29:$E29)) -> 4.9886848 | I14: =SQRT(SUMXMY2($B14:$E14,$B30:$E30)) -> 1.2810636 | J14: =MATCH(MIN(G14:I14),G14:I14,0) -> 3 | K14: =SQRT(SUMXMY2($B14:$E14,$B33:$E33)) -> 1.9726015 | L14: =SQRT(SUMXMY2($B14:$E14,$B34:$E34)) -> 4.254604 | M14: =SQRT(SUMXMY2($B14:$E14,$B35:$E35)) -> 0.5404167 | N14: =MATCH(MIN(K14:M14),K14:M14,0) -> 3 | O14: =SQRT(SUMXMY2($B14:$E14,$B38:$E38)) -> 1.9726015 | P14: =SQRT(SUMXMY2($B14:$E14,$B39:$E39)) -> 4.254604 | Q14: =SQRT(SUMXMY2($B14:$E14,$B40:$E40)) -> 0.5404167 | R14: =MATCH(MIN(O14:Q14),O14:Q14,0) -> 3 | S14: =SQRT(SUMXMY2($B14:$E14,$B43:$E43)) -> 1.9726015 | T14: =SQRT(SUMXMY2($B14:$E14,$B44:$E44)) -> 4.254604 | U14: =SQRT(SUMXMY2($B14:$E14,$B45:$E45)) -> 0.5404167 | V14: =MATCH(MIN(S14:U14),S14:U14,0) -> 3 | W14: =SQRT(SUMXMY2($B14:$E14,$B48:$E48)) -> 1.9726015 | X14: =SQRT(SUMXMY2($B14:$E14,$B49:$E49)) -> 4.254604 | Y14: =SQRT(SUMXMY2($B14:$E14,$B50:$E50)) -> 0.5404167 | Z14: =MATCH(MIN(W14:Y14),W14:Y14,0) -> 3 | AA14: =SQRT(SUMXMY2($B14:$E14,$B53:$E53)) -> 1.9726015 | AB14: =SQRT(SUMXMY2($B14:$E14,$B54:$E54)) -> 4.254604 | AC14: =SQRT(SUMXMY2($B14:$E14,$B55:$E55)) -> 0.5404167 | AD14: =MATCH(MIN(AA14:AC14),AA14:AC14,0) -> 3 | AE14: =SQRT(SUMXMY2($B14:$E14,$B58:$E58)) -> 1.9726015 | AF14: =SQRT(SUMXMY2($B14:$E14,$B59:$E59)) -> 4.254604 | AG14: =SQRT(SUMXMY2($B14:$E14,$B60:$E60)) -> 0.5404167 | AH14: =MATCH(MIN(AE14:AG14),AE14:AG14,0) -> 3 | AI14: =SQRT(SUMXMY2($B14:$E14,$B63:$E63)) -> 1.9726015 | AJ14: =SQRT(SUMXMY2($B14:$E14,$B64:$E64)) -> 4.254604 | AK14: =SQRT(SUMXMY2($B14:$E14,$B65:$E65)) -> 0.5404167 | AL14: =MATCH(MIN(AI14:AK14),AI14:AK14,0) -> 3 | AM14: =INDEX(AI14:AK14,AL14) -> 0.5404167
A15: =Features!A15 -> Chemicals & pharmaceuticals | B15: =Features!I15 -> -0.16933799 | C15: =Features!J15 -> -0.85315416 | D15: =Features!K15 -> 0.24064206 | E15: =Features!L15 -> -0.87520479 | F15: =AL15 -> 3 | G15: =SQRT(SUMXMY2($B15:$E15,$B28:$E28)) -> 2.4774916 | H15: =SQRT(SUMXMY2($B15:$E15,$B29:$E29)) -> 5.2725496 | I15: =SQRT(SUMXMY2($B15:$E15,$B30:$E30)) -> 0.76227014 | J15: =MATCH(MIN(G15:I15),G15:I15,0) -> 3 | K15: =SQRT(SUMXMY2($B15:$E15,$B33:$E33)) -> 2.353683 | L15: =SQRT(SUMXMY2($B15:$E15,$B34:$E34)) -> 4.5752497 | M15: =SQRT(SUMXMY2($B15:$E15,$B35:$E35)) -> 0.86222626 | N15: =MATCH(MIN(K15:M15),K15:M15,0) -> 3 | O15: =SQRT(SUMXMY2($B15:$E15,$B38:$E38)) -> 2.353683 | P15: =SQRT(SUMXMY2($B15:$E15,$B39:$E39)) -> 4.5752497 | Q15: =SQRT(SUMXMY2($B15:$E15,$B40:$E40)) -> 0.86222626 | R15: =MATCH(MIN(O15:Q15),O15:Q15,0) -> 3 | S15: =SQRT(SUMXMY2($B15:$E15,$B43:$E43)) -> 2.353683 | T15: =SQRT(SUMXMY2($B15:$E15,$B44:$E44)) -> 4.5752497 | U15: =SQRT(SUMXMY2($B15:$E15,$B45:$E45)) -> 0.86222626 | V15: =MATCH(MIN(S15:U15),S15:U15,0) -> 3 | W15: =SQRT(SUMXMY2($B15:$E15,$B48:$E48)) -> 2.353683 | X15: =SQRT(SUMXMY2($B15:$E15,$B49:$E49)) -> 4.5752497 | Y15: =SQRT(SUMXMY2($B15:$E15,$B50:$E50)) -> 0.86222626 | Z15: =MATCH(MIN(W15:Y15),W15:Y15,0) -> 3 | AA15: =SQRT(SUMXMY2($B15:$E15,$B53:$E53)) -> 2.353683 | AB15: =SQRT(SUMXMY2($B15:$E15,$B54:$E54)) -> 4.5752497 | AC15: =SQRT(SUMXMY2($B15:$E15,$B55:$E55)) -> 0.86222626 | AD15: =MATCH(MIN(AA15:AC15),AA15:AC15,0) -> 3 | AE15: =SQRT(SUMXMY2($B15:$E15,$B58:$E58)) -> 2.353683 | AF15: =SQRT(SUMXMY2($B15:$E15,$B59:$E59)) -> 4.5752497 | AG15: =SQRT(SUMXMY2($B15:$E15,$B60:$E60)) -> 0.86222626 | AH15: =MATCH(MIN(AE15:AG15),AE15:AG15,0) -> 3 | AI15: =SQRT(SUMXMY2($B15:$E15,$B63:$E63)) -> 2.353683 | AJ15: =SQRT(SUMXMY2($B15:$E15,$B64:$E64)) -> 4.5752497 | AK15: =SQRT(SUMXMY2($B15:$E15,$B65:$E65)) -> 0.86222626 | AL15: =MATCH(MIN(AI15:AK15),AI15:AK15,0) -> 3 | AM15: =INDEX(AI15:AK15,AL15) -> 0.86222626
A16: =Features!A16 -> Renewables | B16: =Features!I16 -> -0.70715049 | C16: =Features!J16 -> 0.65045352 | D16: =Features!K16 -> 1.0983144 | E16: =Features!L16 -> -1.0516498 | F16: =AL16 -> 3 | G16: =SQRT(SUMXMY2($B16:$E16,$B28:$E28)) -> 3.5414629 | H16: =SQRT(SUMXMY2($B16:$E16,$B29:$E29)) -> 4.06883 | I16: =SQRT(SUMXMY2($B16:$E16,$B30:$E30)) -> 1.4146136 | J16: =MATCH(MIN(G16:I16),G16:I16,0) -> 3 | K16: =SQRT(SUMXMY2($B16:$E16,$B33:$E33)) -> 3.2719426 | L16: =SQRT(SUMXMY2($B16:$E16,$B34:$E34)) -> 3.5623347 | M16: =SQRT(SUMXMY2($B16:$E16,$B35:$E35)) -> 1.8001355 | N16: =MATCH(MIN(K16:M16),K16:M16,0) -> 3 | O16: =SQRT(SUMXMY2($B16:$E16,$B38:$E38)) -> 3.2719426 | P16: =SQRT(SUMXMY2($B16:$E16,$B39:$E39)) -> 3.5623347 | Q16: =SQRT(SUMXMY2($B16:$E16,$B40:$E40)) -> 1.8001355 | R16: =MATCH(MIN(O16:Q16),O16:Q16,0) -> 3 | S16: =SQRT(SUMXMY2($B16:$E16,$B43:$E43)) -> 3.2719426 | T16: =SQRT(SUMXMY2($B16:$E16,$B44:$E44)) -> 3.5623347 | U16: =SQRT(SUMXMY2($B16:$E16,$B45:$E45)) -> 1.8001355 | V16: =MATCH(MIN(S16:U16),S16:U16,0) -> 3 | W16: =SQRT(SUMXMY2($B16:$E16,$B48:$E48)) -> 3.2719426 | X16: =SQRT(SUMXMY2($B16:$E16,$B49:$E49)) -> 3.5623347 | Y16: =SQRT(SUMXMY2($B16:$E16,$B50:$E50)) -> 1.8001355 | Z16: =MATCH(MIN(W16:Y16),W16:Y16,0) -> 3 | AA16: =SQRT(SUMXMY2($B16:$E16,$B53:$E53)) -> 3.2719426 | AB16: =SQRT(SUMXMY2($B16:$E16,$B54:$E54)) -> 3.5623347 | AC16: =SQRT(SUMXMY2($B16:$E16,$B55:$E55)) -> 1.8001355 | AD16: =MATCH(MIN(AA16:AC16),AA16:AC16,0) -> 3 | AE16: =SQRT(SUMXMY2($B16:$E16,$B58:$E58)) -> 3.2719426 | AF16: =SQRT(SUMXMY2($B16:$E16,$B59:$E59)) -> 3.5623347 | AG16: =SQRT(SUMXMY2($B16:$E16,$B60:$E60)) -> 1.8001355 | AH16: =MATCH(MIN(AE16:AG16),AE16:AG16,0) -> 3 | AI16: =SQRT(SUMXMY2($B16:$E16,$B63:$E63)) -> 3.2719426 | AJ16: =SQRT(SUMXMY2($B16:$E16,$B64:$E64)) -> 3.5623347 | AK16: =SQRT(SUMXMY2($B16:$E16,$B65:$E65)) -> 1.8001355 | AL16: =MATCH(MIN(AI16:AK16),AI16:AK16,0) -> 3 | AM16: =INDEX(AI16:AK16,AL16) -> 1.8001355
A17: =Features!A17 -> Forestry | B17: =Features!I17 -> -1.5007853 | C17: =Features!J17 -> 0.96636831 | D17: =Features!K17 -> 1.8408003 | E17: =Features!L17 -> 2.2160816 | F17: =AL17 -> 2 | G17: =SQRT(SUMXMY2($B17:$E17,$B28:$E28)) -> 5.2905398 | H17: =SQRT(SUMXMY2($B17:$E17,$B29:$E29)) -> 2.5035704 | I17: =SQRT(SUMXMY2($B17:$E17,$B30:$E30)) -> 3.9553615 | J17: =MATCH(MIN(G17:I17),G17:I17,0) -> 2 | K17: =SQRT(SUMXMY2($B17:$E17,$B33:$E33)) -> 4.7678225 | L17: =SQRT(SUMXMY2($B17:$E17,$B34:$E34)) -> 1.2517852 | M17: =SQRT(SUMXMY2($B17:$E17,$B35:$E35)) -> 3.7394495 | N17: =MATCH(MIN(K17:M17),K17:M17,0) -> 2 | O17: =SQRT(SUMXMY2($B17:$E17,$B38:$E38)) -> 4.7678225 | P17: =SQRT(SUMXMY2($B17:$E17,$B39:$E39)) -> 1.2517852 | Q17: =SQRT(SUMXMY2($B17:$E17,$B40:$E40)) -> 3.7394495 | R17: =MATCH(MIN(O17:Q17),O17:Q17,0) -> 2 | S17: =SQRT(SUMXMY2($B17:$E17,$B43:$E43)) -> 4.7678225 | T17: =SQRT(SUMXMY2($B17:$E17,$B44:$E44)) -> 1.2517852 | U17: =SQRT(SUMXMY2($B17:$E17,$B45:$E45)) -> 3.7394495 | V17: =MATCH(MIN(S17:U17),S17:U17,0) -> 2 | W17: =SQRT(SUMXMY2($B17:$E17,$B48:$E48)) -> 4.7678225 | X17: =SQRT(SUMXMY2($B17:$E17,$B49:$E49)) -> 1.2517852 | Y17: =SQRT(SUMXMY2($B17:$E17,$B50:$E50)) -> 3.7394495 | Z17: =MATCH(MIN(W17:Y17),W17:Y17,0) -> 2 | AA17: =SQRT(SUMXMY2($B17:$E17,$B53:$E53)) -> 4.7678225 | AB17: =SQRT(SUMXMY2($B17:$E17,$B54:$E54)) -> 1.2517852 | AC17: =SQRT(SUMXMY2($B17:$E17,$B55:$E55)) -> 3.7394495 | AD17: =MATCH(MIN(AA17:AC17),AA17:AC17,0) -> 2 | AE17: =SQRT(SUMXMY2($B17:$E17,$B58:$E58)) -> 4.7678225 | AF17: =SQRT(SUMXMY2($B17:$E17,$B59:$E59)) -> 1.2517852 | AG17: =SQRT(SUMXMY2($B17:$E17,$B60:$E60)) -> 3.7394495 | AH17: =MATCH(MIN(AE17:AG17),AE17:AG17,0) -> 2 | AI17: =SQRT(SUMXMY2($B17:$E17,$B63:$E63)) -> 4.7678225 | AJ17: =SQRT(SUMXMY2($B17:$E17,$B64:$E64)) -> 1.2517852 | AK17: =SQRT(SUMXMY2($B17:$E17,$B65:$E65)) -> 3.7394495 | AL17: =MATCH(MIN(AI17:AK17),AI17:AK17,0) -> 2 | AM17: =INDEX(AI17:AK17,AL17) -> 1.2517852
